Workbook
Name Slicer_Attrition: #N/A
Name Slicer_Department: #N/A
Name Slicer_Gender: #N/A
Name Slicer_Job_Role: #N/A
Name Slicer_Work_Mode: #N/A

Sheet Employees
A1: Employee_ID | B1: Employee_Name | C1: Gender | D1: Age | E1: Department | F1: Job_Role | G1: Education | H1: Experience_Years | I1: Joining_Date | J1: Salary | K1: Bonus | L1: Performance_Rating | M1: Work_Mode | N1: City | O1: Attrition | P1: Overtime | Q1: Training_Hours | R1: Leaves_Taken | S1: Satisfaction_Score | T1: Promotion_Status | U1: Age_Group_Colummn | V1: Salary_Band | W1: Experience_Level | X1: Department_ID (VLOOKUP) | Y1: Department_ID(Index+Match) | Z1: Salary_band(Index+Match)
A2: EMP001 | B2: Renee Roy | C2: Male | D2: 23 | E2: Operations | F2: Operations Executive | G2: M.Tech | H2: 0 | I2: 44227 | J2: 57098 | K2: 15825 | L2: 2 | M2: Remote | N2: Delhi | O2: No | P2: Yes | Q2: 18 | R2: 7 | S2: 3 | T2: Not Promoted | U2: =IF(AND(Employees_Data[[#This Row],[Age]]>=20,Employees_Data[[#This Row],[Age]]<=30),"Young",IF(AND(Employees_Data[[#This Row],[Age]]>=31,Employees_Data[[#This Row],[Age]]<=40),"Mid-Age",IF(Employees_Data[[#This Row],[Age]]>=41,"Senior"))) -> Young | V2: =IF(Employees_Data[[#This Row],[Salary]]<=30000,"Low",IF(AND(Employees_Data[[#This Row],[Salary]]>30000,Employees_Data[[#This Row],[Salary]]<=60000),"Medium",IF(AND(Employees_Data[[#This Row],[Salary]]>60000,Employees_Data[[#This Row],[Salary]]<=90000),"High",IF(Employees_Data[[#This Row],[Salary]]>90000,"Executive")))) -> Medium | W2: =IF(Employees_Data[[#This Row],[Experience_Years]]<=2,"Fresher",IF(AND(Employees_Data[[#This Row],[Experience_Years]]>=3,Employees_Data[[#This Row],[Experience_Years]]<=5),"Junior",IF(AND(Employees_Data[[#This Row],[Experience_Years]]>=6,Employees_Data[[#This Row],[Experience_Years]]<=10),"Mid-Level",IF(Employees_Data[[#This Row],[Experience_Years]]>10,"Senior")))) -> Fresher | X2: =VLOOKUP(Employees_Data[[#This Row],[Department]],Departments!$A$2:$B$7,2,FALSE) -> D06 | Y2: =INDEX(Departments!$B$2:$B$7,MATCH(Employees_Data[[#This Row],[Department]],Departments!$A$2:$A$7,0)) -> D06 | Z2: =INDEX(Salary_Bands!$C$2:$C$5,MATCH(Employees_Data[[#This Row],[Salary]],Salary_Bands!$A$2:$A$5,1)) -> Medium | AC2: Employees in department
A3: EMP002 | B3: Anika Ramaswamy | C3: Male | D3: 23 | E3: Marketing | F3: Marketing Manager | G3: Post Graduate | H3: 0 | I3: 43915 | J3: 118850 | K3: 24876 | L3: 5 | M3: Hybrid | N3: Bangalore | O3: No | P3: No | Q3: 14 | R3: 6 | S3: 7 | T3: Not Promoted | U3: =IF(AND(Employees_Data[[#This Row],[Age]]>=20,Employees_Data[[#This Row],[Age]]<=30),"Young",IF(AND(Employees_Data[[#This Row],[Age]]>=31,Employees_Data[[#This Row],[Age]]<=40),"Mid-Age",IF(Employees_Data[[#This Row],[Age]]>=41,"Senior"))) -> Young | V3: =IF(Employees_Data[[#This Row],[Salary]]<=30000,"Low",IF(AND(Employees_Data[[#This Row],[Salary]]>30000,Employees_Data[[#This Row],[Salary]]<=60000),"Medium",IF(AND(Employees_Data[[#This Row],[Salary]]>60000,Employees_Data[[#This Row],[Salary]]<=90000),"High",IF(Employees_Data[[#This Row],[Salary]]>90000,"Executive")))) -> Executive | W3: =IF(Employees_Data[[#This Row],[Experience_Years]]<=2,"Fresher",IF(AND(Employees_Data[[#This Row],[Experience_Years]]>=3,Employees_Data[[#This Row],[Experience_Years]]<=5),"Junior",IF(AND(Employees_Data[[#This Row],[Experience_Years]]>=6,Employees_Data[[#This Row],[Experience_Years]]<=10),"Mid-Level",IF(Employees_Data[[#This Row],[Experience_Years]]>10,"Senior")))) -> Fresher | X3: =VLOOKUP(Employees_Data[[#This Row],[Department]],Departments!$A$2:$B$7,2,FALSE) -> D05 | Y3: =INDEX(Departments!$B$2:$B$7,MATCH(Employees_Data[[#This Row],[Department]],Departments!$A$2:$A$7,0)) -> D05 | Z3: =INDEX(Salary_Bands!$C$2:$C$5,MATCH(Employees_Data[[#This Row],[Salary]],Salary_Bands!$A$2:$A$5,1)) -> Executive | AC3: Finance | AD3: =COUNTIF(Employees_Data[Department],AC3) -> 81
A4: EMP003 | B4: Neysa Jain | C4: Female | D4: 27 | E4: IT | F4: Data Analyst | G4: M.Tech | H4: 3 | I4: 43497 | J4: 72052 | K4: 6090 | L4: 3 | M4: Hybrid | N4: Delhi | O4: No | P4: No | Q4: 58 | R4: 20 | S4: 10 | T4: Promoted | U4: =IF(AND(Employees_Data[[#This Row],[Age]]>=20,Employees_Data[[#This Row],[Age]]<=30),"Young",IF(AND(Employees_Data[[#This Row],[Age]]>=31,Employees_Data[[#This Row],[Age]]<=40),"Mid-Age",IF(Employees_Data[[#This Row],[Age]]>=41,"Senior"))) -> Young | V4: =IF(Employees_Data[[#This Row],[Salary]]<=30000,"Low",IF(AND(Employees_Data[[#This Row],[Salary]]>30000,Employees_Data[[#This Row],[Salary]]<=60000),"Medium",IF(AND(Employees_Data[[#This Row],[Salary]]>60000,Employees_Data[[#This Row],[Salary]]<=90000),"High",IF(Employees_Data[[#This Row],[Salary]]>90000,"Executive")))) -> High | W4: =IF(Employees_Data[[#This Row],[Experience_Years]]<=2,"Fresher",IF(AND(Employees_Data[[#This Row],[Experience_Years]]>=3,Employees_Data[[#This Row],[Experience_Years]]<=5),"Junior",IF(AND(Employees_Data[[#This Row],[Experience_Years]]>=6,Employees_Data[[#This Row],[Experience_Years]]<=10),"Mid-Level",IF(Employees_Data[[#This Row],[Experience_Years]]>10,"Senior")))) -> Junior | X4: =VLOOKUP(Employees_Data[[#This Row],[Department]],Departments!$A$2:$B$7,2,FALSE) -> D03 | Y4: =INDEX(Departments!$B$2:$B$7,MATCH(Employees_Data[[#This Row],[Department]],Departments!$A$2:$A$7,0)) -> D03 | Z4: =INDEX(Salary_Bands!$C$2:$C$5,MATCH(Employees_Data[[#This Row],[Salary]],Salary_Bands!$A$2:$A$5,1)) -> High | AC4: HR | AD4: =COUNTIF(Employees_Data[Department],AC4) -> 83
A5: EMP004 | B5: Taimur Sehgal | C5: Male | D5: 34 | E5: Marketing | F5: Content Strategist | G5: B.Tech | H5: 8 | I5: 43385 | J5: 31006 | K5: 11108 | L5: 2 | M5: Hybrid | N5: Chennai | O5: No | P5: No | Q5: 15 | R5: 11 | S5: 5 | T5: Not Promoted | U5: =IF(AND(Employees_Data[[#This Row],[Age]]>=20,Employees_Data[[#This Row],[Age]]<=30),"Young",IF(AND(Employees_Data[[#This Row],[Age]]>=31,Employees_Data[[#This Row],[Age]]<=40),"Mid-Age",IF(Employees_Data[[#This Row],[Age]]>=41,"Senior"))) -> Mid-Age | V5: =IF(Employees_Data[[#This Row],[Salary]]<=30000,"Low",IF(AND(Employees_Data[[#This Row],[Salary]]>30000,Employees_Data[[#This Row],[Salary]]<=60000),"Medium",IF(AND(Employees_Data[[#This Row],[Salary]]>60000,Employees_Data[[#This Row],[Salary]]<=90000),"High",IF(Employees_Data[[#This Row],[Salary]]>90000,"Executive")))) -> Medium | W5: =IF(Employees_Data[[#This Row],[Experience_Years]]<=2,"Fresher",IF(AND(Employees_Data[[#This Row],[Experience_Years]]>=3,Employees_Data[[#This Row],[Experience_Years]]<=5),"Junior",IF(AND(Employees_Data[[#This Row],[Experience_Years]]>=6,Employees_Data[[#This Row],[Experience_Years]]<=10),"Mid-Level",IF(Employees_Data[[#This Row],[Experience_Years]]>10,"Senior")))) -> Mid-Level | X5: =VLOOKUP(Employees_Data[[#This Row],[Department]],Departments!$A$2:$B$7,2,FALSE) -> D05 | Y5: =INDEX(Departments!$B$2:$B$7,MATCH(Employees_Data[[#This Row],[Department]],Departments!$A$2:$A$7,0)) -> D05 | Z5: =INDEX(Salary_Bands!$C$2:$C$5,MATCH(Employees_Data[[#This Row],[Salary]],Salary_Bands!$A$2:$A$5,1)) -> Medium | AC5: IT | AD5: =COUNTIF(Employees_Data[Department],AC5) -> 86
A6: EMP005 | B6: Kimaya Kade | C6: Female | D6: 39 | E6: IT | F6: Data Analyst | G6: MBA | H6: 13 | I6: 43393 | J6: 104840 | K6: 22971 | L6: 2 | M6: Office | N6: Pune | O6: No | P6: Yes | Q6: 48 | R6: 10 | S6: 9 | T6: Promoted | U6: =IF(AND(Employees_Data[[#This Row],[Age]]>=20,Employees_Data[[#This Row],[Age]]<=30),"Young",IF(AND(Employees_Data[[#This Row],[Age]]>=31,Employees_Data[[#This Row],[Age]]<=40),"Mid-Age",IF(Employees_Data[[#This Row],[Age]]>=41,"Senior"))) -> Mid-Age | V6: =IF(Employees_Data[[#This Row],[Salary]]<=30000,"Low",IF(AND(Employees_Data[[#This Row],[Salary]]>30000,Employees_Data[[#This Row],[Salary]]<=60000),"Medium",IF(AND(Employees_Data[[#This Row],[Salary]]>60000,Employees_Data[[#This Row],[Salary]]<=90000),"High",IF(Employees_Data[[#This Row],[Salary]]>90000,"Executive")))) -> Executive | W6: =IF(Employees_Data[[#This Row],[Experience_Years]]<=2,"Fresher",IF(AND(Employees_Data[[#This Row],[Experience_Years]]>=3,Employees_Data[[#This Row],[Experience_Years]]<=5),"Junior",IF(AND(Employees_Data[[#This Row],[Experience_Years]]>=6,Employees_Data[[#This Row],[Experience_Years]]<=10),"Mid-Level",IF(Employees_Data[[#This Row],[Experience_Years]]>10,"Senior")))) -> Senior | X6: =VLOOKUP(Employees_Data[[#This Row],[Department]],Departments!$A$2:$B$7,2,FALSE) -> D03 | Y6: =INDEX(Departments!$B$2:$B$7,MATCH(Employees_Data[[#This Row],[Department]],Departments!$A$2:$A$7,0)) -> D03 | Z6: =INDEX(Salary_Bands!$C$2:$C$5,MATCH(Employees_Data[[#This Row],[Salary]],Salary_Bands!$A$2:$A$5,1)) -> Executive | AC6: Marketing | AD6: =COUNTIF(Employees_Data[Department],AC6) -> 86
A7: EMP006 | B7: Lakshit Bir | C7: Female | D7: 24 | E7: HR | F7: HR Executive | G7: Post Graduate | H7: 1 | I7: 44744 | J7: 60093 | K7: 23477 | L7: 1 | M7: Hybrid | N7: Hyderabad | O7: No | P7: No | Q7: 14 | R7: 8 | S7: 4 | T7: Not Promoted | U7: =IF(AND(Employees_Data[[#This Row],[Age]]>=20,Employees_Data[[#This Row],[Age]]<=30),"Young",IF(AND(Employees_Data[[#This Row],[Age]]>=31,Employees_Data[[#This Row],[Age]]<=40),"Mid-Age",IF(Employees_Data[[#This Row],[Age]]>=41,"Senior"))) -> Young | V7: =IF(Employees_Data[[#This Row],[Salary]]<=30000,"Low",IF(AND(Employees_Data[[#This Row],[Salary]]>30000,Employees_Data[[#This Row],[Salary]]<=60000),"Medium",IF(AND(Employees_Data[[#This Row],[Salary]]>60000,Employees_Data[[#This Row],[Salary]]<=90000),"High",IF(Employees_Data[[#This Row],[Salary]]>90000,"Executive")))) -> High | W7: =IF(Employees_Data[[#This Row],[Experience_Years]]<=2,"Fresher",IF(AND(Employees_Data[[#This Row],[Experience_Years]]>=3,Employees_Data[[#This Row],[Experience_Years]]<=5),"Junior",IF(AND(Employees_Data[[#This Row],[Experience_Years]]>=6,Employees_Data[[#This Row],[Experience_Years]]<=10),"Mid-Level",IF(Employees_Data[[#This Row],[Experience_Years]]>10,"Senior")))) -> Fresher | X7: =VLOOKUP(Employees_Data[[#This Row],[Department]],Departments!$A$2:$B$7,2,FALSE) -> D01 | Y7: =INDEX(Departments!$B$2:$B$7,MATCH(Employees_Data[[#This Row],[Department]],Departments!$A$2:$A$7,0)) -> D01 | Z7: =INDEX(Salary_Bands!$C$2:$C$5,MATCH(Employees_Data[[#This Row],[Salary]],Salary_Bands!$A$2:$A$5,1)) -> High | AC7: Operations | AD7: =COUNTIF(Employees_Data[Department],AC7) -> 85
A8: EMP007 | B8: Sara Khosla | C8: Male | D8: 38 | E8: Sales | F8: Sales Executive | G8: M.Tech | H8: 12 | I8: 45495 | J8: 81155 | K8: 18171 | L8: 5 | M8: Remote | N8: Noida | O8: No | P8: Yes | Q8: 60 | R8: 3 | S8: 7 | T8: Not Promoted | U8: =IF(AND(Employees_Data[[#This Row],[Age]]>=20,Employees_Data[[#This Row],[Age]]<=30),"Young",IF(AND(Employees_Data[[#This Row],[Age]]>=31,Employees_Data[[#This Row],[Age]]<=40),"Mid-Age",IF(Employees_Data[[#This Row],[Age]]>=41,"Senior"))) -> Mid-Age | V8: =IF(Employees_Data[[#This Row],[Salary]]<=30000,"Low",IF(AND(Employees_Data[[#This Row],[Salary]]>30000,Employees_Data[[#This Row],[Salary]]<=60000),"Medium",IF(AND(Employees_Data[[#This Row],[Salary]]>60000,Employees_Data[[#This Row],[Salary]]<=90000),"High",IF(Employees_Data[[#This Row],[Salary]]>90000,"Executive")))) -> High | W8: =IF(Employees_Data[[#This Row],[Experience_Years]]<=2,"Fresher",IF(AND(Employees_Data[[#This Row],[Experience_Years]]>=3,Employees_Data[[#This Row],[Experience_Years]]<=5),"Junior",IF(AND(Employees_Data[[#This Row],[Experience_Years]]>=6,Employees_Data[[#This Row],[Experience_Years]]<=10),"Mid-Level",IF(Employees_Data[[#This Row],[Experience_Years]]>10,"Senior")))) -> Senior | X8: =VLOOKUP(Employees_Data[[#This Row],[Department]],Departments!$A$2:$B$7,2,FALSE) -> D02 | Y8: =INDEX(Departments!$B$2:$B$7,MATCH(Employees_Data[[#This Row],[Department]],Departments!$A$2:$A$7,0)) -> D02 | Z8: =INDEX(Salary_Bands!$C$2:$C$5,MATCH(Employees_Data[[#This Row],[Salary]],Salary_Bands!$A$2:$A$5,1)) -> High | AC8: Sales | AD8: =COUNTIF(Employees_Data[Department],AC8) -> 79
A9: EMP008 | B9: Romil Baria | C9: Female | D9: 32 | E9: Sales | F9: Business Development Associate | G9: M.Tech | H9: 6 | I9: 44830 | J9: 103172 | K9: 2376 | L9: 1 | M9: Office | N9: Chennai | O9: No | P9: Yes | Q9: 48 | R9: 17 | S9: 7 | T9: Not Promoted | U9: =IF(AND(Employees_Data[[#This Row],[Age]]>=20,Employees_Data[[#This Row],[Age]]<=30),"Young",IF(AND(Employees_Data[[#This Row],[Age]]>=31,Employees_Data[[#This Row],[Age]]<=40),"Mid-Age",IF(Employees_Data[[#This Row],[Age]]>=41,"Senior"))) -> Mid-Age | V9: =IF(Employees_Data[[#This Row],[Salary]]<=30000,"Low",IF(AND(Employees_Data[[#This Row],[Salary]]>30000,Employees_Data[[#This Row],[Salary]]<=60000),"Medium",IF(AND(Employees_Data[[#This Row],[Salary]]>60000,Employees_Data[[#This Row],[Salary]]<=90000),"High",IF(Employees_Data[[#This Row],[Salary]]>90000,"Executive")))) -> Executive | W9: =IF(Employees_Data[[#This Row],[Experience_Years]]<=2,"Fresher",IF(AND(Employees_Data[[#This Row],[Experience_Years]]>=3,Employees_Data[[#This Row],[Experience_Years]]<=5),"Junior",IF(AND(Employees_Data[[#This Row],[Experience_Years]]>=6,Employees_Data[[#This Row],[Experience_Years]]<=10),"Mid-Level",IF(Employees_Data[[#This Row],[Experience_Years]]>10,"Senior")))) -> Mid-Level | X9: =VLOOKUP(Employees_Data[[#This Row],[Department]],Departments!$A$2:$B$7,2,FALSE) -> D02 | Y9: =INDEX(Departments!$B$2:$B$7,MATCH(Employees_Data[[#This Row],[Department]],Departments!$A$2:$A$7,0)) -> D02 | Z9: =INDEX(Salary_Bands!$C$2:$C$5,MATCH(Employees_Data[[#This Row],[Salary]],Salary_Bands!$A$2:$A$5,1)) -> Executive
A10: EMP009 | B10: Aarna Gopal | C10: Female | D10: 43 | E10: IT | F10: System Administrator | G10: M.Tech | H10: 22 | I10: 44303 | J10: 81985 | K10: 7854 | L10: 2 | M10: Office | N10: Delhi | O10: Yes | P10: No | Q10: 58 | R10: 20 | S10: 8 | T10: Not Promoted | U10: =IF(AND(Employees_Data[[#This Row],[Age]]>=20,Employees_Data[[#This Row],[Age]]<=30),"Young",IF(AND(Employees_Data[[#This Row],[Age]]>=31,Employees_Data[[#This Row],[Age]]<=40),"Mid-Age",IF(Employees_Data[[#This Row],[Age]]>=41,"Senior"))) -> Senior | V10: =IF(Employees_Data[[#This Row],[Salary]]<=30000,"Low",IF(AND(Employees_Data[[#This Row],[Salary]]>30000,Employees_Data[[#This Row],[Salary]]<=60000),"Medium",IF(AND(Employees_Data[[#This Row],[Salary]]>60000,Employees_Data[[#This Row],[Salary]]<=90000),"High",IF(Employees_Data[[#This Row],[Salary]]>90000,"Executive")))) -> High | W10: =IF(Employees_Data[[#This Row],[Experience_Years]]<=2,"Fresher",IF(AND(Employees_Data[[#This Row],[Experience_Years]]>=3,Employees_Data[[#This Row],[Experience_Years]]<=5),"Junior",IF(AND(Employees_Data[[#This Row],[Experience_Years]]>=6,Employees_Data[[#This Row],[Experience_Years]]<=10),"Mid-Level",IF(Employees_Data[[#This Row],[Experience_Years]]>10,"Senior")))) -> Senior | X10: =VLOOKUP(Employees_Data[[#This Row],[Department]],Departments!$A$2:$B$7,2,FALSE) -> D03 | Y10: =INDEX(Departments!$B$2:$B$7,MATCH(Employees_Data[[#This Row],[Department]],Departments!$A$2:$A$7,0)) -> D03 | Z10: =INDEX(Salary_Bands!$C$2:$C$5,MATCH(Employees_Data[[#This Row],[Salary]],Salary_Bands!$A$2:$A$5,1)) -> High | AC10: Maximum Salary | AD10: =MAX(Employees_Data[Salary]) -> 149122
A11: EMP010 | B11: Biju Tella | C11: Male | D11: 34 | E11: Marketing | F11: Marketing Manager | G11: M.Tech | H11: 12 | I11: 44632 | J11: 124943 | K11: 12621 | L11: 2 | M11: Hybrid | N11: Delhi | O11: No | P11: Yes | Q11: 28 | R11: 9 | S11: 9 | T11: Not Promoted | U11: =IF(AND(Employees_Data[[#This Row],[Age]]>=20,Employees_Data[[#This Row],[Age]]<=30),"Young",IF(AND(Employees_Data[[#This Row],[Age]]>=31,Employees_Data[[#This Row],[Age]]<=40),"Mid-Age",IF(Employees_Data[[#This Row],[Age]]>=41,"Senior"))) -> Mid-Age | V11: =IF(Employees_Data[[#This Row],[Salary]]<=30000,"Low",IF(AND(Employees_Data[[#This Row],[Salary]]>30000,Employees_Data[[#This Row],[Salary]]<=60000),"Medium",IF(AND(Employees_Data[[#This Row],[Salary]]>60000,Employees_Data[[#This Row],[Salary]]<=90000),"High",IF(Employees_Data[[#This Row],[Salary]]>90000,"Executive")))) -> Executive | W11: =IF(Employees_Data[[#This Row],[Experience_Years]]<=2,"Fresher",IF(AND(Employees_Data[[#This Row],[Experience_Years]]>=3,Employees_Data[[#This Row],[Experience_Years]]<=5),"Junior",IF(AND(Employees_Data[[#This Row],[Experience_Years]]>=6,Employees_Data[[#This Row],[Experience_Years]]<=10),"Mid-Level",IF(Employees_Data[[#This Row],[Experience_Years]]>10,"Senior")))) -> Senior | X11: =VLOOKUP(Employees_Data[[#This Row],[Department]],Departments!$A$2:$B$7,2,FALSE) -> D05 | Y11: =INDEX(Departments!$B$2:$B$7,MATCH(Employees_Data[[#This Row],[Department]],Departments!$A$2:$A$7,0)) -> D05 | Z11: =INDEX(Salary_Bands!$C$2:$C$5,MATCH(Employees_Data[[#This Row],[Salary]],Salary_Bands!$A$2:$A$5,1)) -> Executive
A12: EMP011 | B12: Ranbir Sant | C12: Male | D12: 37 | E12: Sales | F12: Sales Executive | G12: Post Graduate | H12: 12 | I12: 43423 | J12: 36226 | K12: 23618 | L12: 4 | M12: Hybrid | N12: Pune | O12: No | P12: Yes | Q12: 21 | R12: 16 | S12: 2 | T12: Not Promoted | U12: =IF(AND(Employees_Data[[#This Row],[Age]]>=20,Employees_Data[[#This Row],[Age]]<=30),"Young",IF(AND(Employees_Data[[#This Row],[Age]]>=31,Employees_Data[[#This Row],[Age]]<=40),"Mid-Age",IF(Employees_Data[[#This Row],[Age]]>=41,"Senior"))) -> Mid-Age | V12: =IF(Employees_Data[[#This Row],[Salary]]<=30000,"Low",IF(AND(Employees_Data[[#This Row],[Salary]]>30000,Employees_Data[[#This Row],[Salary]]<=60000),"Medium",IF(AND(Employees_Data[[#This Row],[Salary]]>60000,Employees_Data[[#This Row],[Salary]]<=90000),"High",IF(Employees_Data[[#This Row],[Salary]]>90000,"Executive")))) -> Medium | W12: =IF(Employees_Data[[#This Row],[Experience_Years]]<=2,"Fresher",IF(AND(Employees_Data[[#This Row],[Experience_Years]]>=3,Employees_Data[[#This Row],[Experience_Years]]<=5),"Junior",IF(AND(Employees_Data[[#This Row],[Experience_Years]]>=6,Employees_Data[[#This Row],[Experience_Years]]<=10),"Mid-Level",IF(Employees_Data[[#This Row],[Experience_Years]]>10,"Senior")))) -> Senior | X12: =VLOOKUP(Employees_Data[[#This Row],[Department]],Departments!$A$2:$B$7,2,FALSE) -> D02 | Y12: =INDEX(Departments!$B$2:$B$7,MATCH(Employees_Data[[#This Row],[Department]],Departments!$A$2:$A$7,0)) -> D02 | Z12: =INDEX(Salary_Bands!$C$2:$C$5,MATCH(Employees_Data[[#This Row],[Salary]],Salary_Bands!$A$2:$A$5,1)) -> Medium | AC12: Minimum salary | AD12: =MIN(Employees_Data[Salary]) -> 25142
A13: EMP012 | B13: Tejas Agate | C13: Female | D13: 35 | E13: Marketing | F13: Content Strategist | G13: M.Tech | H13: 10 | I13: 43924 | J13: 118447 | K13: 16794 | L13: 3 | M13: Remote | N13: Mumbai | O13: No | P13: Yes | Q13: 9 | R13: 10 | S13: 7 | T13: Not Promoted | U13: =IF(AND(Employees_Data[[#This Row],[Age]]>=20,Employees_Data[[#This Row],[Age]]<=30),"Young",IF(AND(Employees_Data[[#This Row],[Age]]>=31,Employees_Data[[#This Row],[Age]]<=40),"Mid-Age",IF(Employees_Data[[#This Row],[Age]]>=41,"Senior"))) -> Mid-Age | V13: =IF(Employees_Data[[#This Row],[Salary]]<=30000,"Low",IF(AND(Employees_Data[[#This Row],[Salary]]>30000,Employees_Data[[#This Row],[Salary]]<=60000),"Medium",IF(AND(Employees_Data[[#This Row],[Salary]]>60000,Employees_Data[[#This Row],[Salary]]<=90000),"High",IF(Employees_Data[[#This Row],[Salary]]>90000,"Executive")))) -> Executive | W13: =IF(Employees_Data[[#This Row],[Experience_Years]]<=2,"Fresher",IF(AND(Employees_Data[[#This Row],[Experience_Years]]>=3,Employees_Data[[#This Row],[Experience_Years]]<=5),"Junior",IF(AND(Employees_Data[[#This Row],[Experience_Years]]>=6,Employees_Data[[#This Row],[Experience_Years]]<=10),"Mid-Level",IF(Employees_Data[[#This Row],[Experience_Years]]>10,"Senior")))) -> Mid-Level | X13: =VLOOKUP(Employees_Data[[#This Row],[Department]],Departments!$A$2:$B$7,2,FALSE) -> D05 | Y13: =INDEX(Departments!$B$2:$B$7,MATCH(Employees_Data[[#This Row],[Department]],Departments!$A$2:$A$7,0)) -> D05 | Z13: =INDEX(Salary_Bands!$C$2:$C$5,MATCH(Employees_Data[[#This Row],[Salary]],Salary_Bands!$A$2:$A$5,1)) -> Executive
A14: EMP013 | B14: Hazel Kibe | C14: Female | D14: 36 | E14: HR | F14: HR Manager | G14: Graduate | H14: 11 | I14: 44003 | J14: 25942 | K14: 18847 | L14: 1 | M14: Remote | N14: Bangalore | O14: No | P14: No | Q14: 18 | R14: 17 | S14: 1 | T14: Not Promoted | U14: =IF(AND(Employees_Data[[#This Row],[Age]]>=20,Employees_Data[[#This Row],[Age]]<=30),"Young",IF(AND(Employees_Data[[#This Row],[Age]]>=31,Employees_Data[[#This Row],[Age]]<=40),"Mid-Age",IF(Employees_Data[[#This Row],[Age]]>=41,"Senior"))) -> Mid-Age | V14: =IF(Employees_Data[[#This Row],[Salary]]<=30000,"Low",IF(AND(Employees_Data[[#This Row],[Salary]]>30000,Employees_Data[[#This Row],[Salary]]<=60000),"Medium",IF(AND(Employees_Data[[#This Row],[Salary]]>60000,Employees_Data[[#This Row],[Salary]]<=90000),"High",IF(Employees_Data[[#This Row],[Salary]]>90000,"Executive")))) -> Low | W14: =IF(Employees_Data[[#This Row],[Experience_Years]]<=2,"Fresher",IF(AND(Employees_Data[[#This Row],[Experience_Years]]>=3,Employees_Data[[#This Row],[Experience_Years]]<=5),"Junior",IF(AND(Employees_Data[[#This Row],[Experience_Years]]>=6,Employees_Data[[#This Row],[Experience_Years]]<=10),"Mid-Level",IF(Employees_Data[[#This Row],[Experience_Years]]>10,"Senior")))) -> Senior | X14: =VLOOKUP(Employees_Data[[#This Row],[Department]],Departments!$A$2:$B$7,2,FALSE) -> D01 | Y14: =INDEX(Departments!$B$2:$B$7,MATCH(Employees_Data[[#This Row],[Department]],Departments!$A$2:$A$7,0)) -> D01 | Z14: =INDEX(Salary_Bands!$C$2:$C$5,MATCH(Employees_Data[[#This Row],[Salary]],Salary_Bands!$A$2:$A$5,1)) -> Low | AC14: Total Number Of Employees Left
A15: EMP014 | B15: Prerak Chanda | C15: Female | D15: 52 | E15: Sales | F15: Business Development Associate | G15: B.Tech | H15: 30 | I15: 45038 | J15: 130840 | K15: 15470 | L15: 4 | M15: Hybrid | N15: Noida | O15: Yes | P15: Yes | Q15: 48 | R15: 20 | S15: 4 | T15: Not Promoted | U15: =IF(AND(Employees_Data[[#This Row],[Age]]>=20,Employees_Data[[#This Row],[Age]]<=30),"Young",IF(AND(Employees_Data[[#This Row],[Age]]>=31,Employees_Data[[#This Row],[Age]]<=40),"Mid-Age",IF(Employees_Data[[#This Row],[Age]]>=41,"Senior"))) -> Senior | V15: =IF(Employees_Data[[#This Row],[Salary]]<=30000,"Low",IF(AND(Employees_Data[[#This Row],[Salary]]>30000,Employees_Data[[#This Row],[Salary]]<=60000),"Medium",IF(AND(Employees_Data[[#This Row],[Salary]]>60000,Employees_Data[[#This Row],[Salary]]<=90000),"High",IF(Employees_Data[[#This Row],[Salary]]>90000,"Executive")))) -> Executive | W15: =IF(Employees_Data[[#This Row],[Experience_Years]]<=2,"Fresher",IF(AND(Employees_Data[[#This Row],[Experience_Years]]>=3,Employees_Data[[#This Row],[Experience_Years]]<=5),"Junior",IF(AND(Employees_Data[[#This Row],[Experience_Years]]>=6,Employees_Data[[#This Row],[Experience_Years]]<=10),"Mid-Level",IF(Employees_Data[[#This Row],[Experience_Years]]>10,"Senior")))) -> Senior | X15: =VLOOKUP(Employees_Data[[#This Row],[Department]],Departments!$A$2:$B$7,2,FALSE) -> D02 | Y15: =INDEX(Departments!$B$2:$B$7,MATCH(Employees_Data[[#This Row],[Department]],Departments!$A$2:$A$7,0)) -> D02 | Z15: =INDEX(Salary_Bands!$C$2:$C$5,MATCH(Employees_Data[[#This Row],[Salary]],Salary_Bands!$A$2:$A$5,1)) -> Executive | AC15: =COUNTIF(Employees_Data[Attrition],"Yes") -> 74
A16: EMP015 | B16: Urvi Keer | C16: Male | D16: 25 | E16: Operations | F16: Operations Executive | G16: B.Tech | H16: 1 | I16: 44490 | J16: 129935 | K16: 8012 | L16: 1 | M16: Hybrid | N16: Hyderabad | O16: No | P16: Yes | Q16: 60 | R16: 2 | S16: 4 | T16: Not Promoted | U16: =IF(AND(Employees_Data[[#This Row],[Age]]>=20,Employees_Data[[#This Row],[Age]]<=30),"Young",IF(AND(Employees_Data[[#This Row],[Age]]>=31,Employees_Data[[#This Row],[Age]]<=40),"Mid-Age",IF(Employees_Data[[#This Row],[Age]]>=41,"Senior"))) -> Young | V16: =IF(Employees_Data[[#This Row],[Salary]]<=30000,"Low",IF(AND(Employees_Data[[#This Row],[Salary]]>30000,Employees_Data[[#This Row],[Salary]]<=60000),"Medium",IF(AND(Employees_Data[[#This Row],[Salary]]>60000,Employees_Data[[#This Row],[Salary]]<=90000),"High",IF(Employees_Data[[#This Row],[Salary]]>90000,"Executive")))) -> Executive | W16: =IF(Employees_Data[[#This Row],[Experience_Years]]<=2,"Fresher",IF(AND(Employees_Data[[#This Row],[Experience_Years]]>=3,Employees_Data[[#This Row],[Experience_Years]]<=5),"Junior",IF(AND(Employees_Data[[#This Row],[Experience_Years]]>=6,Employees_Data[[#This Row],[Experience_Years]]<=10),"Mid-Level",IF(Employees_Data[[#This Row],[Experience_Years]]>10,"Senior")))) -> Fresher | X16: =VLOOKUP(Employees_Data[[#This Row],[Department]],Departments!$A$2:$B$7,2,FALSE) -> D06 | Y16: =INDEX(Departments!$B$2:$B$7,MATCH(Employees_Data[[#This Row],[Department]],Departments!$A$2:$A$7,0)) -> D06 | Z16: =INDEX(Salary_Bands!$C$2:$C$5,MATCH(Employees_Data[[#This Row],[Salary]],Salary_Bands!$A$2:$A$5,1)) -> Executive
A17: EMP016 | B17: Saksham Verma | C17: Male | D17: 28 | E17: Finance | F17: Finance Manager | G17: B.Tech | H17: 7 | I17: 45315 | J17: 134579 | K17: 17913 | L17: 1 | M17: Hybrid | N17: Mumbai | O17: No | P17: No | Q17: 8 | R17: 5 | S17: 2 | T17: Not Promoted | U17: =IF(AND(Employees_Data[[#This Row],[Age]]>=20,Employees_Data[[#This Row],[Age]]<=30),"Young",IF(AND(Employees_Data[[#This Row],[Age]]>=31,Employees_Data[[#This Row],[Age]]<=40),"Mid-Age",IF(Employees_Data[[#This Row],[Age]]>=41,"Senior"))) -> Young | V17: =IF(Employees_Data[[#This Row],[Salary]]<=30000,"Low",IF(AND(Employees_Data[[#This Row],[Salary]]>30000,Employees_Data[[#This Row],[Salary]]<=60000),"Medium",IF(AND(Employees_Data[[#This Row],[Salary]]>60000,Employees_Data[[#This Row],[Salary]]<=90000),"High",IF(Employees_Data[[#This Row],[Salary]]>90000,"Executive")))) -> Executive | W17: =IF(Employees_Data[[#This Row],[Experience_Years]]<=2,"Fresher",IF(AND(Employees_Data[[#This Row],[Experience_Years]]>=3,Employees_Data[[#This Row],[Experience_Years]]<=5),"Junior",IF(AND(Employees_Data[[#This Row],[Experience_Years]]>=6,Employees_Data[[#This Row],[Experience_Years]]<=10),"Mid-Level",IF(Employees_Data[[#This Row],[Experience_Years]]>10,"Senior")))) -> Mid-Level | X17: =VLOOKUP(Employees_Data[[#This Row],[Department]],Departments!$A$2:$B$7,2,FALSE) -> D04 | Y17: =INDEX(Departments!$B$2:$B$7,MATCH(Employees_Data[[#This Row],[Department]],Departments!$A$2:$A$7,0)) -> D04 | Z17: =INDEX(Salary_Bands!$C$2:$C$5,MATCH(Employees_Data[[#This Row],[Salary]],Salary_Bands!$A$2:$A$5,1)) -> Executive | AC17: Total Employees in Cities
A18: EMP017 | B18: Sumer Date | C18: Male | D18: 46 | E18: Finance | F18: Accountant | G18: MBA | H18: 23 | I18: 44964 | J18: 62388 | K18: 9133 | L18: 4 | M18: Remote | N18: Pune | O18: No | P18: Yes | Q18: 52 | R18: 10 | S18: 9 | T18: Not Promoted | U18: =IF(AND(Employees_Data[[#This Row],[Age]]>=20,Employees_Data[[#This Row],[Age]]<=30),"Young",IF(AND(Employees_Data[[#This Row],[Age]]>=31,Employees_Data[[#This Row],[Age]]<=40),"Mid-Age",IF(Employees_Data[[#This Row],[Age]]>=41,"Senior"))) -> Senior | V18: =IF(Employees_Data[[#This Row],[Salary]]<=30000,"Low",IF(AND(Employees_Data[[#This Row],[Salary]]>30000,Employees_Data[[#This Row],[Salary]]<=60000),"Medium",IF(AND(Employees_Data[[#This Row],[Salary]]>60000,Employees_Data[[#This Row],[Salary]]<=90000),"High",IF(Employees_Data[[#This Row],[Salary]]>90000,"Executive")))) -> High | W18: =IF(Employees_Data[[#This Row],[Experience_Years]]<=2,"Fresher",IF(AND(Employees_Data[[#This Row],[Experience_Years]]>=3,Employees_Data[[#This Row],[Experience_Years]]<=5),"Junior",IF(AND(Employees_Data[[#This Row],[Experience_Years]]>=6,Employees_Data[[#This Row],[Experience_Years]]<=10),"Mid-Level",IF(Employees_Data[[#This Row],[Experience_Years]]>10,"Senior")))) -> Senior | X18: =VLOOKUP(Employees_Data[[#This Row],[Department]],Departments!$A$2:$B$7,2,FALSE) -> D04 | Y18: =INDEX(Departments!$B$2:$B$7,MATCH(Employees_Data[[#This Row],[Department]],Departments!$A$2:$A$7,0)) -> D04 | Z18: =INDEX(Salary_Bands!$C$2:$C$5,MATCH(Employees_Data[[#This Row],[Salary]],Salary_Bands!$A$2:$A$5,1)) -> High | AC18: Chennai | AD18: =COUNTIF(Employees_Data[City],AC18) -> 74
A19: EMP018 | B19: Elakshi Banerjee | C19: Male | D19: 52 | E19: HR | F19: HR Executive | G19: Post Graduate | H19: 27 | I19: 45276 | J19: 45635 | K19: 15230 | L19: 1 | M19: Remote | N19: Pune | O19: Yes | P19: Yes | Q19: 42 | R19: 19 | S19: 9 | T19: Promoted | U19: =IF(AND(Employees_Data[[#This Row],[Age]]>=20,Employees_Data[[#This Row],[Age]]<=30),"Young",IF(AND(Employees_Data[[#This Row],[Age]]>=31,Employees_Data[[#This Row],[Age]]<=40),"Mid-Age",IF(Employees_Data[[#This Row],[Age]]>=41,"Senior"))) -> Senior | V19: =IF(Employees_Data[[#This Row],[Salary]]<=30000,"Low",IF(AND(Employees_Data[[#This Row],[Salary]]>30000,Employees_Data[[#This Row],[Salary]]<=60000),"Medium",IF(AND(Employees_Data[[#This Row],[Salary]]>60000,Employees_Data[[#This Row],[Salary]]<=90000),"High",IF(Employees_Data[[#This Row],[Salary]]>90000,"Executive")))) -> Medium | W19: =IF(Employees_Data[[#This Row],[Experience_Years]]<=2,"Fresher",IF(AND(Employees_Data[[#This Row],[Experience_Years]]>=3,Employees_Data[[#This Row],[Experience_Years]]<=5),"Junior",IF(AND(Employees_Data[[#This Row],[Experience_Years]]>=6,Employees_Data[[#This Row],[Experience_Years]]<=10),"Mid-Level",IF(Employees_Data[[#This Row],[Experience_Years]]>10,"Senior")))) -> Senior | X19: =VLOOKUP(Employees_Data[[#This Row],[Department]],Departments!$A$2:$B$7,2,FALSE) -> D01 | Y19: =INDEX(Departments!$B$2:$B$7,MATCH(Employees_Data[[#This Row],[Department]],Departments!$A$2:$A$7,0)) -> D01 | Z19: =INDEX(Salary_Bands!$C$2:$C$5,MATCH(Employees_Data[[#This Row],[Salary]],Salary_Bands!$A$2:$A$5,1)) -> Medium | AC19: Pune | AD19: =COUNTIF(Employees_Data[City],AC19) -> 56
A20: EMP019 | B20: Samaira Raman | C20: Female | D20: 27 | E20: HR | F20: HR Manager | G20: Post Graduate | H20: 3 | I20: 45491 | J20: 99085 | K20: 10703 | L20: 5 | M20: Hybrid | N20: Mumbai | O20: No | P20: No | Q20: 34 | R20: 10 | S20: 6 | T20: Not Promoted | U20: =IF(AND(Employees_Data[[#This Row],[Age]]>=20,Employees_Data[[#This Row],[Age]]<=30),"Young",IF(AND(Employees_Data[[#This Row],[Age]]>=31,Employees_Data[[#This Row],[Age]]<=40),"Mid-Age",IF(Employees_Data[[#This Row],[Age]]>=41,"Senior"))) -> Young | V20: =IF(Employees_Data[[#This Row],[Salary]]<=30000,"Low",IF(AND(Employees_Data[[#This Row],[Salary]]>30000,Employees_Data[[#This Row],[Salary]]<=60000),"Medium",IF(AND(Employees_Data[[#This Row],[Salary]]>60000,Employees_Data[[#This Row],[Salary]]<=90000),"High",IF(Employees_Data[[#This Row],[Salary]]>90000,"Executive")))) -> Executive | W20: =IF(Employees_Data[[#This Row],[Experience_Years]]<=2,"Fresher",IF(AND(Employees_Data[[#This Row],[Experience_Years]]>=3,Employees_Data[[#This Row],[Experience_Years]]<=5),"Junior",IF(AND(Employees_Data[[#This Row],[Experience_Years]]>=6,Employees_Data[[#This Row],[Experience_Years]]<=10),"Mid-Level",IF(Employees_Data[[#This Row],[Experience_Years]]>10,"Senior")))) -> Junior | X20: =VLOOKUP(Employees_Data[[#This Row],[Department]],Departments!$A$2:$B$7,2,FALSE) -> D01 | Y20: =INDEX(Departments!$B$2:$B$7,MATCH(Employees_Data[[#This Row],[Department]],Departments!$A$2:$A$7,0)) -> D01 | Z20: =INDEX(Salary_Bands!$C$2:$C$5,MATCH(Employees_Data[[#This Row],[Salary]],Salary_Bands!$A$2:$A$5,1)) -> Executive | AC20: Hyderabad | AD20: =COUNTIF(Employees_Data[City],AC20) -> 75
A21: EMP020 | B21: Kartik Gara | C21: Female | D21: 51 | E21: HR | F21: HR Executive | G21: Graduate | H21: 26 | I21: 45407 | J21: 38104 | K21: 10004 | L21: 1 | M21: Hybrid | N21: Bangalore | O21: No | P21: Yes | Q21: 33 | R21: 17 | S21: 9 | T21: Not Promoted | U21: =IF(AND(Employees_Data[[#This Row],[Age]]>=20,Employees_Data[[#This Row],[Age]]<=30),"Young",IF(AND(Employees_Data[[#This Row],[Age]]>=31,Employees_Data[[#This Row],[Age]]<=40),"Mid-Age",IF(Employees_Data[[#This Row],[Age]]>=41,"Senior"))) -> Senior | V21: =IF(Employees_Data[[#This Row],[Salary]]<=30000,"Low",IF(AND(Employees_Data[[#This Row],[Salary]]>30000,Employees_Data[[#This Row],[Salary]]<=60000),"Medium",IF(AND(Employees_Data[[#This Row],[Salary]]>60000,Employees_Data[[#This Row],[Salary]]<=90000),"High",IF(Employees_Data[[#This Row],[Salary]]>90000,"Executive")))) -> Medium | W21: =IF(Employees_Data[[#This Row],[Experience_Years]]<=2,"Fresher",IF(AND(Employees_Data[[#This Row],[Experience_Years]]>=3,Employees_Data[[#This Row],[Experience_Years]]<=5),"Junior",IF(AND(Employees_Data[[#This Row],[Experience_Years]]>=6,Employees_Data[[#This Row],[Experience_Years]]<=10),"Mid-Level",IF(Employees_Data[[#This Row],[Experience_Years]]>10,"Senior")))) -> Senior | X21: =VLOOKUP(Employees_Data[[#This Row],[Department]],Departments!$A$2:$B$7,2,FALSE) -> D01 | Y21: =INDEX(Departments!$B$2:$B$7,MATCH(Employees_Data[[#This Row],[Department]],Departments!$A$2:$A$7,0)) -> D01 | Z21: =INDEX(Salary_Bands!$C$2:$C$5,MATCH(Employees_Data[[#This Row],[Salary]],Salary_Bands!$A$2:$A$5,1)) -> Medium | AC21: Noida | AD21: =COUNTIF(Employees_Data[City],AC21) -> 81
A22: EMP021 | B22: Anay Dugal | C22: Male | D22: 55 | E22: Operations | F22: Supply Chain Analyst | G22: MBA | H22: 34 | I22: 45372 | J22: 64240 | K22: 11232 | L22: 1 | M22: Office | N22: Mumbai | O22: No | P22: No | Q22: 18 | R22: 20 | S22: 3 | T22: Not Promoted | U22: =IF(AND(Employees_Data[[#This Row],[Age]]>=20,Employees_Data[[#This Row],[Age]]<=30),"Young",IF(AND(Employees_Data[[#This Row],[Age]]>=31,Employees_Data[[#This Row],[Age]]<=40),"Mid-Age",IF(Employees_Data[[#This Row],[Age]]>=41,"Senior"))) -> Senior | V22: =IF(Employees_Data[[#This Row],[Salary]]<=30000,"Low",IF(AND(Employees_Data[[#This Row],[Salary]]>30000,Employees_Data[[#This Row],[Salary]]<=60000),"Medium",IF(AND(Employees_Data[[#This Row],[Salary]]>60000,Employees_Data[[#This Row],[Salary]]<=90000),"High",IF(Employees_Data[[#This Row],[Salary]]>90000,"Executive")))) -> High | W22: =IF(Employees_Data[[#This Row],[Experience_Years]]<=2,"Fresher",IF(AND(Employees_Data[[#This Row],[Experience_Years]]>=3,Employees_Data[[#This Row],[Experience_Years]]<=5),"Junior",IF(AND(Employees_Data[[#This Row],[Experience_Years]]>=6,Employees_Data[[#This Row],[Experience_Years]]<=10),"Mid-Level",IF(Employees_Data[[#This Row],[Experience_Years]]>10,"Senior")))) -> Senior | X22: =VLOOKUP(Employees_Data[[#This Row],[Department]],Departments!$A$2:$B$7,2,FALSE) -> D06 | Y22: =INDEX(Departments!$B$2:$B$7,MATCH(Employees_Data[[#This Row],[Department]],Departments!$A$2:$A$7,0)) -> D06 | Z22: =INDEX(Salary_Bands!$C$2:$C$5,MATCH(Employees_Data[[#This Row],[Salary]],Salary_Bands!$A$2:$A$5,1)) -> High | AC22: Mumbai | AD22: =COUNTIF(Employees_Data[City],AC22) -> 68
A23: EMP022 | B23: Zain Gandhi | C23: Male | D23: 53 | E23: IT | F23: System Administrator | G23: MBA | H23: 30 | I23: 43309 | J23: 37097 | K23: 7294 | L23: 4 | M23: Office | N23: Hyderabad | O23: Yes | P23: No | Q23: 40 | R23: 0 | S23: 5 | T23: Not Promoted | U23: =IF(AND(Employees_Data[[#This Row],[Age]]>=20,Employees_Data[[#This Row],[Age]]<=30),"Young",IF(AND(Employees_Data[[#This Row],[Age]]>=31,Employees_Data[[#This Row],[Age]]<=40),"Mid-Age",IF(Employees_Data[[#This Row],[Age]]>=41,"Senior"))) -> Senior | V23: =IF(Employees_Data[[#This Row],[Salary]]<=30000,"Low",IF(AND(Employees_Data[[#This Row],[Salary]]>30000,Employees_Data[[#This Row],[Salary]]<=60000),"Medium",IF(AND(Employees_Data[[#This Row],[Salary]]>60000,Employees_Data[[#This Row],[Salary]]<=90000),"High",IF(Employees_Data[[#This Row],[Salary]]>90000,"Executive")))) -> Medium | W23: =IF(Employees_Data[[#This Row],[Experience_Years]]<=2,"Fresher",IF(AND(Employees_Data[[#This Row],[Experience_Years]]>=3,Employees_Data[[#This Row],[Experience_Years]]<=5),"Junior",IF(AND(Employees_Data[[#This Row],[Experience_Years]]>=6,Employees_Data[[#This Row],[Experience_Years]]<=10),"Mid-Level",IF(Employees_Data[[#This Row],[Experience_Years]]>10,"Senior")))) -> Senior | X23: =VLOOKUP(Employees_Data[[#This Row],[Department]],Departments!$A$2:$B$7,2,FALSE) -> D03 | Y23: =INDEX(Departments!$B$2:$B$7,MATCH(Employees_Data[[#This Row],[Department]],Departments!$A$2:$A$7,0)) -> D03 | Z23: =INDEX(Salary_Bands!$C$2:$C$5,MATCH(Employees_Data[[#This Row],[Salary]],Salary_Bands!$A$2:$A$5,1)) -> Medium | AC23: Bangalore | AD23: =COUNTIF(Employees_Data[City],AC23) -> 76
A24: EMP023 | B24: Tushar Joshi | C24: Male | D24: 31 | E24: HR | F24: HR Executive | G24: MBA | H24: 6 | I24: 43248 | J24: 134392 | K24: 13948 | L24: 3 | M24: Remote | N24: Bangalore | O24: No | P24: Yes | Q24: 48 | R24: 7 | S24: 10 | T24: Not Promoted | U24: =IF(AND(Employees_Data[[#This Row],[Age]]>=20,Employees_Data[[#This Row],[Age]]<=30),"Young",IF(AND(Employees_Data[[#This Row],[Age]]>=31,Employees_Data[[#This Row],[Age]]<=40),"Mid-Age",IF(Employees_Data[[#This Row],[Age]]>=41,"Senior"))) -> Mid-Age | V24: =IF(Employees_Data[[#This Row],[Salary]]<=30000,"Low",IF(AND(Employees_Data[[#This Row],[Salary]]>30000,Employees_Data[[#This Row],[Salary]]<=60000),"Medium",IF(AND(Employees_Data[[#This Row],[Salary]]>60000,Employees_Data[[#This Row],[Salary]]<=90000),"High",IF(Employees_Data[[#This Row],[Salary]]>90000,"Executive")))) -> Executive | W24: =IF(Employees_Data[[#This Row],[Experience_Years]]<=2,"Fresher",IF(AND(Employees_Data[[#This Row],[Experience_Years]]>=3,Employees_Data[[#This Row],[Experience_Years]]<=5),"Junior",IF(AND(Employees_Data[[#This Row],[Experience_Years]]>=6,Employees_Data[[#This Row],[Experience_Years]]<=10),"Mid-Level",IF(Employees_Data[[#This Row],[Experience_Years]]>10,"Senior")))) -> Mid-Level | X24: =VLOOKUP(Employees_Data[[#This Row],[Department]],Departments!$A$2:$B$7,2,FALSE) -> D01 | Y24: =INDEX(Departments!$B$2:$B$7,MATCH(Employees_Data[[#This Row],[Department]],Departments!$A$2:$A$7,0)) -> D01 | Z24: =INDEX(Salary_Bands!$C$2:$C$5,MATCH(Employees_Data[[#This Row],[Salary]],Salary_Bands!$A$2:$A$5,1)) -> Executive | AC24: Delhi | AD24: =COUNTIF(Employees_Data[City],AC24) -> 70
A25: EMP024 | B25: Anaya Chaudhary | C25: Male | D25: 44 | E25: Operations | F25: Operations Executive | G25: B.Tech | H25: 19 | I25: 44765 | J25: 106351 | K25: 2812 | L25: 2 | M25: Remote | N25: Chennai | O25: No | P25: No | Q25: 55 | R25: 13 | S25: 4 | T25: Not Promoted | U25: =IF(AND(Employees_Data[[#This Row],[Age]]>=20,Employees_Data[[#This Row],[Age]]<=30),"Young",IF(AND(Employees_Data[[#This Row],[Age]]>=31,Employees_Data[[#This Row],[Age]]<=40),"Mid-Age",IF(Employees_Data[[#This Row],[Age]]>=41,"Senior"))) -> Senior | V25: =IF(Employees_Data[[#This Row],[Salary]]<=30000,"Low",IF(AND(Employees_Data[[#This Row],[Salary]]>30000,Employees_Data[[#This Row],[Salary]]<=60000),"Medium",IF(AND(Employees_Data[[#This Row],[Salary]]>60000,Employees_Data[[#This Row],[Salary]]<=90000),"High",IF(Employees_Data[[#This Row],[Salary]]>90000,"Executive")))) -> Executive | W25: =IF(Employees_Data[[#This Row],[Experience_Years]]<=2,"Fresher",IF(AND(Employees_Data[[#This Row],[Experience_Years]]>=3,Employees_Data[[#This Row],[Experience_Years]]<=5),"Junior",IF(AND(Employees_Data[[#This Row],[Experience_Years]]>=6,Employees_Data[[#This Row],[Experience_Years]]<=10),"Mid-Level",IF(Employees_Data[[#This Row],[Experience_Years]]>10,"Senior")))) -> Senior | X25: =VLOOKUP(Employees_Data[[#This Row],[Department]],Departments!$A$2:$B$7,2,FALSE) -> D06 | Y25: =INDEX(Departments!$B$2:$B$7,MATCH(Employees_Data[[#This Row],[Department]],Departments!$A$2:$A$7,0)) -> D06 | Z25: =INDEX(Salary_Bands!$C$2:$C$5,MATCH(Employees_Data[[#This Row],[Salary]],Salary_Bands!$A$2:$A$5,1)) -> Executive
A26: EMP025 | B26: Neelofar Chatterjee | C26: Male | D26: 37 | E26: Operations | F26: Operations Manager | G26: Post Graduate | H26: 14 | I26: 43753 | J26: 128202 | K26: 17083 | L26: 1 | M26: Hybrid | N26: Bangalore | O26: No | P26: Yes | Q26: 19 | R26: 0 | S26: 7 | T26: Not Promoted | U26: =IF(AND(Employees_Data[[#This Row],[Age]]>=20,Employees_Data[[#This Row],[Age]]<=30),"Young",IF(AND(Employees_Data[[#This Row],[Age]]>=31,Employees_Data[[#This Row],[Age]]<=40),"Mid-Age",IF(Employees_Data[[#This Row],[Age]]>=41,"Senior"))) -> Mid-Age | V26: =IF(Employees_Data[[#This Row],[Salary]]<=30000,"Low",IF(AND(Employees_Data[[#This Row],[Salary]]>30000,Employees_Data[[#This Row],[Salary]]<=60000),"Medium",IF(AND(Employees_Data[[#This Row],[Salary]]>60000,Employees_Data[[#This Row],[Salary]]<=90000),"High",IF(Employees_Data[[#This Row],[Salary]]>90000,"Executive")))) -> Executive | W26: =IF(Employees_Data[[#This Row],[Experience_Years]]<=2,"Fresher",IF(AND(Employees_Data[[#This Row],[Experience_Years]]>=3,Employees_Data[[#This Row],[Experience_Years]]<=5),"Junior",IF(AND(Employees_Data[[#This Row],[Experience_Years]]>=6,Employees_Data[[#This Row],[Experience_Years]]<=10),"Mid-Level",IF(Employees_Data[[#This Row],[Experience_Years]]>10,"Senior")))) -> Senior | X26: =VLOOKUP(Employees_Data[[#This Row],[Department]],Departments!$A$2:$B$7,2,FALSE) -> D06 | Y26: =INDEX(Departments!$B$2:$B$7,MATCH(Employees_Data[[#This Row],[Department]],Departments!$A$2:$A$7,0)) -> D06 | Z26: =INDEX(Salary_Bands!$C$2:$C$5,MATCH(Employees_Data[[#This Row],[Salary]],Salary_Bands!$A$2:$A$5,1)) -> Executive | AC26: Average Salary of Department
A27: EMP026 | B27: Romil Sachdeva | C27: Female | D27: 47 | E27: Operations | F27: Operations Executive | G27: Graduate | H27: 24 | I27: 44242 | J27: 138292 | K27: 5779 | L27: 1 | M27: Hybrid | N27: Mumbai | O27: No | P27: No | Q27: 7 | R27: 3 | S27: 5 | T27: Not Promoted | U27: =IF(AND(Employees_Data[[#This Row],[Age]]>=20,Employees_Data[[#This Row],[Age]]<=30),"Young",IF(AND(Employees_Data[[#This Row],[Age]]>=31,Employees_Data[[#This Row],[Age]]<=40),"Mid-Age",IF(Employees_Data[[#This Row],[Age]]>=41,"Senior"))) -> Senior | V27: =IF(Employees_Data[[#This Row],[Salary]]<=30000,"Low",IF(AND(Employees_Data[[#This Row],[Salary]]>30000,Employees_Data[[#This Row],[Salary]]<=60000),"Medium",IF(AND(Employees_Data[[#This Row],[Salary]]>60000,Employees_Data[[#This Row],[Salary]]<=90000),"High",IF(Employees_Data[[#This Row],[Salary]]>90000,"Executive")))) -> Executive | W27: =IF(Employees_Data[[#This Row],[Experience_Years]]<=2,"Fresher",IF(AND(Employees_Data[[#This Row],[Experience_Years]]>=3,Employees_Data[[#This Row],[Experience_Years]]<=5),"Junior",IF(AND(Employees_Data[[#This Row],[Experience_Years]]>=6,Employees_Data[[#This Row],[Experience_Years]]<=10),"Mid-Level",IF(Employees_Data[[#This Row],[Experience_Years]]>10,"Senior")))) -> Senior | X27: =VLOOKUP(Employees_Data[[#This Row],[Department]],Departments!$A$2:$B$7,2,FALSE) -> D06 | Y27: =INDEX(Departments!$B$2:$B$7,MATCH(Employees_Data[[#This Row],[Department]],Departments!$A$2:$A$7,0)) -> D06 | Z27: =INDEX(Salary_Bands!$C$2:$C$5,MATCH(Employees_Data[[#This Row],[Salary]],Salary_Bands!$A$2:$A$5,1)) -> Executive | AC27: =AVERAGEIF(Employees_Data[Department],"HR",Employees_Data[Salary]) -> 86779.289
A28: EMP027 | B28: Indrajit Kohli | C28: Male | D28: 44 | E28: Marketing | F28: Content Strategist | G28: MBA | H28: 18 | I28: 44385 | J28: 82199 | K28: 3454 | L28: 5 | M28: Office | N28: Hyderabad | O28: Yes | P28: Yes | Q28: 38 | R28: 17 | S28: 9 | T28: Not Promoted | U28: =IF(AND(Employees_Data[[#This Row],[Age]]>=20,Employees_Data[[#This Row],[Age]]<=30),"Young",IF(AND(Employees_Data[[#This Row],[Age]]>=31,Employees_Data[[#This Row],[Age]]<=40),"Mid-Age",IF(Employees_Data[[#This Row],[Age]]>=41,"Senior"))) -> Senior | V28: =IF(Employees_Data[[#This Row],[Salary]]<=30000,"Low",IF(AND(Employees_Data[[#This Row],[Salary]]>30000,Employees_Data[[#This Row],[Salary]]<=60000),"Medium",IF(AND(Employees_Data[[#This Row],[Salary]]>60000,Employees_Data[[#This Row],[Salary]]<=90000),"High",IF(Employees_Data[[#This Row],[Salary]]>90000,"Executive")))) -> High | W28: =IF(Employees_Data[[#This Row],[Experience_Years]]<=2,"Fresher",IF(AND(Employees_Data[[#This Row],[Experience_Years]]>=3,Employees_Data[[#This Row],[Experience_Years]]<=5),"Junior",IF(AND(Employees_Data[[#This Row],[Experience_Years]]>=6,Employees_Data[[#This Row],[Experience_Years]]<=10),"Mid-Level",IF(Employees_Data[[#This Row],[Experience_Years]]>10,"Senior")))) -> Senior | X28: =VLOOKUP(Employees_Data[[#This Row],[Department]],Departments!$A$2:$B$7,2,FALSE) -> D05 | Y28: =INDEX(Departments!$B$2:$B$7,MATCH(Employees_Data[[#This Row],[Department]],Departments!$A$2:$A$7,0)) -> D05 | Z28: =INDEX(Salary_Bands!$C$2:$C$5,MATCH(Employees_Data[[#This Row],[Salary]],Salary_Bands!$A$2:$A$5,1)) -> High
A29: EMP028 | B29: Rania Karpe | C29: Female | D29: 34 | E29: Operations | F29: Operations Manager | G29: M.Tech | H29: 11 | I29: 44867 | J29: 34171 | K29: 12134 | L29: 3 | M29: Office | N29: Hyderabad | O29: No | P29: No | Q29: 30 | R29: 9 | S29: 10 | T29: Not Promoted | U29: =IF(AND(Employees_Data[[#This Row],[Age]]>=20,Employees_Data[[#This Row],[Age]]<=30),"Young",IF(AND(Employees_Data[[#This Row],[Age]]>=31,Employees_Data[[#This Row],[Age]]<=40),"Mid-Age",IF(Employees_Data[[#This Row],[Age]]>=41,"Senior"))) -> Mid-Age | V29: =IF(Employees_Data[[#This Row],[Salary]]<=30000,"Low",IF(AND(Employees_Data[[#This Row],[Salary]]>30000,Employees_Data[[#This Row],[Salary]]<=60000),"Medium",IF(AND(Employees_Data[[#This Row],[Salary]]>60000,Employees_Data[[#This Row],[Salary]]<=90000),"High",IF(Employees_Data[[#This Row],[Salary]]>90000,"Executive")))) -> Medium | W29: =IF(Employees_Data[[#This Row],[Experience_Years]]<=2,"Fresher",IF(AND(Employees_Data[[#This Row],[Experience_Years]]>=3,Employees_Data[[#This Row],[Experience_Years]]<=5),"Junior",IF(AND(Employees_Data[[#This Row],[Experience_Years]]>=6,Employees_Data[[#This Row],[Experience_Years]]<=10),"Mid-Level",IF(Employees_Data[[#This Row],[Experience_Years]]>10,"Senior")))) -> Senior | X29: =VLOOKUP(Employees_Data[[#This Row],[Department]],Departments!$A$2:$B$7,2,FALSE) -> D06 | Y29: =INDEX(Departments!$B$2:$B$7,MATCH(Employees_Data[[#This Row],[Department]],Departments!$A$2:$A$7,0)) -> D06 | Z29: =INDEX(Salary_Bands!$C$2:$C$5,MATCH(Employees_Data[[#This Row],[Salary]],Salary_Bands!$A$2:$A$5,1)) -> Medium | AC29: Count of Remote Employees
A30: EMP029 | B30: Samiha Seth | C30: Male | D30: 34 | E30: Marketing | F30: SEO Specialist | G30: MBA | H30: 10 | I30: 44653 | J30: 113777 | K30: 11401 | L30: 2 | M30: Remote | N30: Hyderabad | O30: No | P30: No | Q30: 34 | R30: 14 | S30: 10 | T30: Not Promoted | U30: =IF(AND(Employees_Data[[#This Row],[Age]]>=20,Employees_Data[[#This Row],[Age]]<=30),"Young",IF(AND(Employees_Data[[#This Row],[Age]]>=31,Employees_Data[[#This Row],[Age]]<=40),"Mid-Age",IF(Employees_Data[[#This Row],[Age]]>=41,"Senior"))) -> Mid-Age | V30: =IF(Employees_Data[[#This Row],[Salary]]<=30000,"Low",IF(AND(Employees_Data[[#This Row],[Salary]]>30000,Employees_Data[[#This Row],[Salary]]<=60000),"Medium",IF(AND(Employees_Data[[#This Row],[Salary]]>60000,Employees_Data[[#This Row],[Salary]]<=90000),"High",IF(Employees_Data[[#This Row],[Salary]]>90000,"Executive")))) -> Executive | W30: =IF(Employees_Data[[#This Row],[Experience_Years]]<=2,"Fresher",IF(AND(Employees_Data[[#This Row],[Experience_Years]]>=3,Employees_Data[[#This Row],[Experience_Years]]<=5),"Junior",IF(AND(Employees_Data[[#This Row],[Experience_Years]]>=6,Employees_Data[[#This Row],[Experience_Years]]<=10),"Mid-Level",IF(Employees_Data[[#This Row],[Experience_Years]]>10,"Senior")))) -> Mid-Level | X30: =VLOOKUP(Employees_Data[[#This Row],[Department]],Departments!$A$2:$B$7,2,FALSE) -> D05 | Y30: =INDEX(Departments!$B$2:$B$7,MATCH(Employees_Data[[#This Row],[Department]],Departments!$A$2:$A$7,0)) -> D05 | Z30: =INDEX(Salary_Bands!$C$2:$C$5,MATCH(Employees_Data[[#This Row],[Salary]],Salary_Bands!$A$2:$A$5,1)) -> Executive | AC30: =COUNTIF(M19:M501,"Remote") -> 155
A31: EMP030 | B31: Shaan Ahluwalia | C31: Female | D31: 35 | E31: Finance | F31: Finance Manager | G31: Graduate | H31: 10 | I31: 45039 | J31: 129036 | K31: 9696 | L31: 2 | M31: Office | N31: Bangalore | O31: No | P31: Yes | Q31: 56 | R31: 6 | S31: 2 | T31: Not Promoted | U31: =IF(AND(Employees_Data[[#This Row],[Age]]>=20,Employees_Data[[#This Row],[Age]]<=30),"Young",IF(AND(Employees_Data[[#This Row],[Age]]>=31,Employees_Data[[#This Row],[Age]]<=40),"Mid-Age",IF(Employees_Data[[#This Row],[Age]]>=41,"Senior"))) -> Mid-Age | V31: =IF(Employees_Data[[#This Row],[Salary]]<=30000,"Low",IF(AND(Employees_Data[[#This Row],[Salary]]>30000,Employees_Data[[#This Row],[Salary]]<=60000),"Medium",IF(AND(Employees_Data[[#This Row],[Salary]]>60000,Employees_Data[[#This Row],[Salary]]<=90000),"High",IF(Employees_Data[[#This Row],[Salary]]>90000,"Executive")))) -> Executive | W31: =IF(Employees_Data[[#This Row],[Experience_Years]]<=2,"Fresher",IF(AND(Employees_Data[[#This Row],[Experience_Years]]>=3,Employees_Data[[#This Row],[Experience_Years]]<=5),"Junior",IF(AND(Employees_Data[[#This Row],[Experience_Years]]>=6,Employees_Data[[#This Row],[Experience_Years]]<=10),"Mid-Level",IF(Employees_Data[[#This Row],[Experience_Years]]>10,"Senior")))) -> Mid-Level | X31: =VLOOKUP(Employees_Data[[#This Row],[Department]],Departments!$A$2:$B$7,2,FALSE) -> D04 | Y31: =INDEX(Departments!$B$2:$B$7,MATCH(Employees_Data[[#This Row],[Department]],Departments!$A$2:$A$7,0)) -> D04 | Z31: =INDEX(Salary_Bands!$C$2:$C$5,MATCH(Employees_Data[[#This Row],[Salary]],Salary_Bands!$A$2:$A$5,1)) -> Executive
A32: EMP031 | B32: Vritika Brahmbhatt | C32: Male | D32: 24 | E32: Sales | F32: Sales Executive | G32: B.Tech | H32: 2 | I32: 45047 | J32: 105120 | K32: 18199 | L32: 1 | M32: Hybrid | N32: Mumbai | O32: No | P32: Yes | Q32: 46 | R32: 0 | S32: 8 | T32: Not Promoted | U32: =IF(AND(Employees_Data[[#This Row],[Age]]>=20,Employees_Data[[#This Row],[Age]]<=30),"Young",IF(AND(Employees_Data[[#This Row],[Age]]>=31,Employees_Data[[#This Row],[Age]]<=40),"Mid-Age",IF(Employees_Data[[#This Row],[Age]]>=41,"Senior"))) -> Young | V32: =IF(Employees_Data[[#This Row],[Salary]]<=30000,"Low",IF(AND(Employees_Data[[#This Row],[Salary]]>30000,Employees_Data[[#This Row],[Salary]]<=60000),"Medium",IF(AND(Employees_Data[[#This Row],[Salary]]>60000,Employees_Data[[#This Row],[Salary]]<=90000),"High",IF(Employees_Data[[#This Row],[Salary]]>90000,"Executive")))) -> Executive | W32: =IF(Employees_Data[[#This Row],[Experience_Years]]<=2,"Fresher",IF(AND(Employees_Data[[#This Row],[Experience_Years]]>=3,Employees_Data[[#This Row],[Experience_Years]]<=5),"Junior",IF(AND(Employees_Data[[#This Row],[Experience_Years]]>=6,Employees_Data[[#This Row],[Experience_Years]]<=10),"Mid-Level",IF(Employees_Data[[#This Row],[Experience_Years]]>10,"Senior")))) -> Fresher | X32: =VLOOKUP(Employees_Data[[#This Row],[Department]],Departments!$A$2:$B$7,2,FALSE) -> D02 | Y32: =INDEX(Departments!$B$2:$B$7,MATCH(Employees_Data[[#This Row],[Department]],Departments!$A$2:$A$7,0)) -> D02 | Z32: =INDEX(Salary_Bands!$C$2:$C$5,MATCH(Employees_Data[[#This Row],[Salary]],Salary_Bands!$A$2:$A$5,1)) -> Executive | AC32: Highest Bonus
A33: EMP032 | B33: Seher Bhatti | C33: Female | D33: 36 | E33: HR | F33: Recruiter | G33: Post Graduate | H33: 14 | I33: 45222 | J33: 85889 | K33: 17225 | L33: 1 | M33: Office | N33: Pune | O33: No | P33: No | Q33: 53 | R33: 14 | S33: 9 | T33: Not Promoted | U33: =IF(AND(Employees_Data[[#This Row],[Age]]>=20,Employees_Data[[#This Row],[Age]]<=30),"Young",IF(AND(Employees_Data[[#This Row],[Age]]>=31,Employees_Data[[#This Row],[Age]]<=40),"Mid-Age",IF(Employees_Data[[#This Row],[Age]]>=41,"Senior"))) -> Mid-Age | V33: =IF(Employees_Data[[#This Row],[Salary]]<=30000,"Low",IF(AND(Employees_Data[[#This Row],[Salary]]>30000,Employees_Data[[#This Row],[Salary]]<=60000),"Medium",IF(AND(Employees_Data[[#This Row],[Salary]]>60000,Employees_Data[[#This Row],[Salary]]<=90000),"High",IF(Employees_Data[[#This Row],[Salary]]>90000,"Executive")))) -> High | W33: =IF(Employees_Data[[#This Row],[Experience_Years]]<=2,"Fresher",IF(AND(Employees_Data[[#This Row],[Experience_Years]]>=3,Employees_Data[[#This Row],[Experience_Years]]<=5),"Junior",IF(AND(Employees_Data[[#This Row],[Experience_Years]]>=6,Employees_Data[[#This Row],[Experience_Years]]<=10),"Mid-Level",IF(Employees_Data[[#This Row],[Experience_Years]]>10,"Senior")))) -> Senior | X33: =VLOOKUP(Employees_Data[[#This Row],[Department]],Departments!$A$2:$B$7,2,FALSE) -> D01 | Y33: =INDEX(Departments!$B$2:$B$7,MATCH(Employees_Data[[#This Row],[Department]],Departments!$A$2:$A$7,0)) -> D01 | Z33: =INDEX(Salary_Bands!$C$2:$C$5,MATCH(Employees_Data[[#This Row],[Salary]],Salary_Bands!$A$2:$A$5,1)) -> High | AC33: =MAX(Employees_Data[Bonus]) -> 24980
A34: EMP033 | B34: Manikya Chaudhuri | C34: Female | D34: 54 | E34: Marketing | F34: Marketing Manager | G34: M.Tech | H34: 30 | I34: 45345 | J34: 83446 | K34: 17879 | L34: 2 | M34: Office | N34: Mumbai | O34: No | P34: No | Q34: 33 | R34: 2 | S34: 8 | T34: Not Promoted | U34: =IF(AND(Employees_Data[[#This Row],[Age]]>=20,Employees_Data[[#This Row],[Age]]<=30),"Young",IF(AND(Employees_Data[[#This Row],[Age]]>=31,Employees_Data[[#This Row],[Age]]<=40),"Mid-Age",IF(Employees_Data[[#This Row],[Age]]>=41,"Senior"))) -> Senior | V34: =IF(Employees_Data[[#This Row],[Salary]]<=30000,"Low",IF(AND(Employees_Data[[#This Row],[Salary]]>30000,Employees_Data[[#This Row],[Salary]]<=60000),"Medium",IF(AND(Employees_Data[[#This Row],[Salary]]>60000,Employees_Data[[#This Row],[Salary]]<=90000),"High",IF(Employees_Data[[#This Row],[Salary]]>90000,"Executive")))) -> High | W34: =IF(Employees_Data[[#This Row],[Experience_Years]]<=2,"Fresher",IF(AND(Employees_Data[[#This Row],[Experience_Years]]>=3,Employees_Data[[#This Row],[Experience_Years]]<=5),"Junior",IF(AND(Employees_Data[[#This Row],[Experience_Years]]>=6,Employees_Data[[#This Row],[Experience_Years]]<=10),"Mid-Level",IF(Employees_Data[[#This Row],[Experience_Years]]>10,"Senior")))) -> Senior | X34: =VLOOKUP(Employees_Data[[#This Row],[Department]],Departments!$A$2:$B$7,2,FALSE) -> D05 | Y34: =INDEX(Departments!$B$2:$B$7,MATCH(Employees_Data[[#This Row],[Department]],Departments!$A$2:$A$7,0)) -> D05 | Z34: =INDEX(Salary_Bands!$C$2:$C$5,MATCH(Employees_Data[[#This Row],[Salary]],Salary_Bands!$A$2:$A$5,1)) -> High
A35: EMP034 | B35: Ishita Roy | C35: Male | D35: 37 | E35: Operations | F35: Supply Chain Analyst | G35: Post Graduate | H35: 14 | I35: 44476 | J35: 66904 | K35: 4104 | L35: 5 | M35: Hybrid | N35: Hyderabad | O35: Yes | P35: No | Q35: 39 | R35: 14 | S35: 2 | T35: Not Promoted | U35: =IF(AND(Employees_Data[[#This Row],[Age]]>=20,Employees_Data[[#This Row],[Age]]<=30),"Young",IF(AND(Employees_Data[[#This Row],[Age]]>=31,Employees_Data[[#This Row],[Age]]<=40),"Mid-Age",IF(Employees_Data[[#This Row],[Age]]>=41,"Senior"))) -> Mid-Age | V35: =IF(Employees_Data[[#This Row],[Salary]]<=30000,"Low",IF(AND(Employees_Data[[#This Row],[Salary]]>30000,Employees_Data[[#This Row],[Salary]]<=60000),"Medium",IF(AND(Employees_Data[[#This Row],[Salary]]>60000,Employees_Data[[#This Row],[Salary]]<=90000),"High",IF(Employees_Data[[#This Row],[Salary]]>90000,"Executive")))) -> High | W35: =IF(Employees_Data[[#This Row],[Experience_Years]]<=2,"Fresher",IF(AND(Employees_Data[[#This Row],[Experience_Years]]>=3,Employees_Data[[#This Row],[Experience_Years]]<=5),"Junior",IF(AND(Employees_Data[[#This Row],[Experience_Years]]>=6,Employees_Data[[#This Row],[Experience_Years]]<=10),"Mid-Level",IF(Employees_Data[[#This Row],[Experience_Years]]>10,"Senior")))) -> Senior | X35: =VLOOKUP(Employees_Data[[#This Row],[Department]],Departments!$A$2:$B$7,2,FALSE) -> D06 | Y35: =INDEX(Departments!$B$2:$B$7,MATCH(Employees_Data[[#This Row],[Department]],Departments!$A$2:$A$7,0)) -> D06 | Z35: =INDEX(Salary_Bands!$C$2:$C$5,MATCH(Employees_Data[[#This Row],[Salary]],Salary_Bands!$A$2:$A$5,1)) -> High
A36: EMP035 | B36: Dhruv Rattan | C36: Female | D36: 35 | E36: Finance | F36: Accountant | G36: B.Tech | H36: 11 | I36: 44696 | J36: 143598 | K36: 2193 | L36: 5 | M36: Hybrid | N36: Bangalore | O36: No | P36: No | Q36: 59 | R36: 13 | S36: 1 | T36: Not Promoted | U36: =IF(AND(Employees_Data[[#This Row],[Age]]>=20,Employees_Data[[#This Row],[Age]]<=30),"Young",IF(AND(Employees_Data[[#This Row],[Age]]>=31,Employees_Data[[#This Row],[Age]]<=40),"Mid-Age",IF(Employees_Data[[#This Row],[Age]]>=41,"Senior"))) -> Mid-Age | V36: =IF(Employees_Data[[#This Row],[Salary]]<=30000,"Low",IF(AND(Employees_Data[[#This Row],[Salary]]>30000,Employees_Data[[#This Row],[Salary]]<=60000),"Medium",IF(AND(Employees_Data[[#This Row],[Salary]]>60000,Employees_Data[[#This Row],[Salary]]<=90000),"High",IF(Employees_Data[[#This Row],[Salary]]>90000,"Executive")))) -> Executive | W36: =IF(Employees_Data[[#This Row],[Experience_Years]]<=2,"Fresher",IF(AND(Employees_Data[[#This Row],[Experience_Years]]>=3,Employees_Data[[#This Row],[Experience_Years]]<=5),"Junior",IF(AND(Employees_Data[[#This Row],[Experience_Years]]>=6,Employees_Data[[#This Row],[Experience_Years]]<=10),"Mid-Level",IF(Employees_Data[[#This Row],[Experience_Years]]>10,"Senior")))) -> Senior | X36: =VLOOKUP(Employees_Data[[#This Row],[Department]],Departments!$A$2:$B$7,2,FALSE) -> D04 | Y36: =INDEX(Departments!$B$2:$B$7,MATCH(Employees_Data[[#This Row],[Department]],Departments!$A$2:$A$7,0)) -> D04 | Z36: =INDEX(Salary_Bands!$C$2:$C$5,MATCH(Employees_Data[[#This Row],[Salary]],Salary_Bands!$A$2:$A$5,1)) -> Executive
A37: EMP036 | B37: Faiyaz Lalla | C37: Female | D37: 36 | E37: Marketing | F37: Marketing Manager | G37: Post Graduate | H37: 12 | I37: 43999 | J37: 60774 | K37: 17315 | L37: 4 | M37: Remote | N37: Pune | O37: Yes | P37: Yes | Q37: 30 | R37: 18 | S37: 8 | T37: Not Promoted | U37: =IF(AND(Employees_Data[[#This Row],[Age]]>=20,Employees_Data[[#This Row],[Age]]<=30),"Young",IF(AND(Employees_Data[[#This Row],[Age]]>=31,Employees_Data[[#This Row],[Age]]<=40),"Mid-Age",IF(Employees_Data[[#This Row],[Age]]>=41,"Senior"))) -> Mid-Age | V37: =IF(Employees_Data[[#This Row],[Salary]]<=30000,"Low",IF(AND(Employees_Data[[#This Row],[Salary]]>30000,Employees_Data[[#This Row],[Salary]]<=60000),"Medium",IF(AND(Employees_Data[[#This Row],[Salary]]>60000,Employees_Data[[#This Row],[Salary]]<=90000),"High",IF(Employees_Data[[#This Row],[Salary]]>90000,"Executive")))) -> High | W37: =IF(Employees_Data[[#This Row],[Experience_Years]]<=2,"Fresher",IF(AND(Employees_Data[[#This Row],[Experience_Years]]>=3,Employees_Data[[#This Row],[Experience_Years]]<=5),"Junior",IF(AND(Employees_Data[[#This Row],[Experience_Years]]>=6,Employees_Data[[#This Row],[Experience_Years]]<=10),"Mid-Level",IF(Employees_Data[[#This Row],[Experience_Years]]>10,"Senior")))) -> Senior | X37: =VLOOKUP(Employees_Data[[#This Row],[Department]],Departments!$A$2:$B$7,2,FALSE) -> D05 | Y37: =INDEX(Departments!$B$2:$B$7,MATCH(Employees_Data[[#This Row],[Department]],Departments!$A$2:$A$7,0)) -> D05 | Z37: =INDEX(Salary_Bands!$C$2:$C$5,MATCH(Employees_Data[[#This Row],[Salary]],Salary_Bands!$A$2:$A$5,1)) -> High
